<?xml version="1.0"?>
<robot name="Single_Joint">

	<link name="Link_1"> 
		<visual>
			<origin xyz="0 0 0.5" rpy="0 0 0"/>
			<geometry>
				<cylinder radius="1" length="1"/>
			</geometry>
			<material name="Cyan">
				<color rgba="0 1.0 1.0 1.0"/>
			</material>
		</visual>

		<collision>
			<origin xyz="0 0 0" rpy="0 0 0"/>
			<geometry>
				<cylinder radius="1" length="1"/>
			</geometry>
		</collision>
	</link>


	<link name="Link_2"> 
		<visual>
			<origin xyz="0 0 1.25" rpy="0 0 0"/>
			<geometry>
				<box size="0.5 5 0.5"/>
			</geometry>
			<material name=" ">
				<color rgba="0.5 0.6 0.6 1" />
			</material>
		</visual>

		<collision>
			<origin xyz="0 0 0.75" rpy="0 0 0"/>
			<geometry>
				<box size="1 5 0.5"/>
			</geometry>
		</collision>
	</link>

	
	<joint name="Joint1" type="revolute">
		<origin xyz="0 0 0" rpy="0 0 0"/>
		<axis xyz="0 0 1"/>
		<parent link="Link_1"/>
		<child link="Link_2"/>
		<limit effort="30" velocity="1" lower="-3.14" upper="3.14"/>
	</joint>

</robot>