<?xml version="1.0" encoding="utf-8"?>
<robot name="single_joint">

	<gazebo>
		<plugin name="gazebo_ros_control" filename="libgazebo_ros_control.so"></plugin>
	</gazebo>

	<link name="link_1"> 
		<visual>
			<origin xyz="0 0 0.5" rpy="0 0 0"/>
			<geometry>
				<cylinder radius="1" length="1"/>
			</geometry>
			<material name="Cyan">
				<color rgba="0 1.0 1.0 1.0"/>
			</material>
		</visual>

		<collision>
			<origin xyz="0 0 0.5" rpy="0 0 0"/>
			<geometry>
				<cylinder radius="1" length="1"/>
			</geometry>
		</collision>

		<inertial>
			<mass value="1.0"/>
			<origin rpy="0 0 0" xyz="0.0 0.0 0.0"/>
			<inertia ixx="0.3333" ixy="0.0" ixz="0.0" 
			         iyy="0.3333" iyz="0.0" izz="0.5"/>
		</inertial>
	</link>


	<link name="link_2"> 
		<visual>
			<origin xyz="0 0 1.25" rpy="0 0 0"/>
			<geometry>
				<box size="0.5 5 0.5"/>
			</geometry>
			<material name=" ">
				<color rgba="0.5 0.6 0.6 1" />
			</material>
		</visual>

		<collision>
			<origin xyz="0 0 1.25" rpy="0 0 0"/>
			<geometry>
				<box size="0.5 5 0.5"/>
			</geometry>
		</collision>

		<inertial>
			<mass value="1.0"/>
			<origin rpy="0 0 0" xyz="0.0 0.0 0.0"/>
			<inertia ixx="2.104" ixy="0.0" ixz="0.0" 
			         iyy="0.04167" iyz="0.0" izz="2.104"/>
		</inertial>
	</link>

	
	<joint name="joint_1" type="revolute">
		<origin xyz="0 0 0" rpy="0 0 0"/>
		<axis xyz="0 0 1"/>
		<parent link="link_1"/>
		<child link="link_2"/>
		<limit effort="30" velocity="1" lower="-3.14" upper="3.14"/>
	</joint>

	<link name="world"/>
	<joint name="world_joint" type="fixed">
		<parent link="world"/>
		<child link="link_1"/>
		<origin rpy="0.0 0.0 0.0" xyz="0.0 0.0 0.0"/>
	</joint>

	<transmission name="joint_1_trans">
		<type>transmission_interface/SimpleTransmission</type>
		<joint name="joint_1">
			<hardwareInterface>EffortJointInterface</hardwareInterface>
		</joint>
		<actuator name="joint_1_motor">
			<mechanicalReduction>1</mechanicalReduction>
		</actuator>
	</transmission>

</robot>